Workbook
Name Alternator: MachinesOnSite!$Z$4:$Z$1048576
Name Battery: MachinesOnSite!$J$4:$J$1048576
Name Cable_size_between__battery__Starter: MachinesOnSite!$AI$4:$AI$1048576
Name Category: MachinesOnSite!$F$4:$F$1048576
Name Electrical__System: MachinesOnSite!$H$4:$H$1048576
Name Engine: MachinesOnSite!$G$4:$G$1048576
Name Link: MachinesOnSite!$AJ$4:$AJ$1048576
Name MachineList: MachinesOnSite!$D$4:$D$1903
Name Manufacturer: MachinesOnSite!$C$4:$C$1048576
Name Site: MachinesOnSite!$B$4:$B$1048576
Name Starter_Motor: MachinesOnSite!$R$4:$R$1048576
Name Type__surface__underground: MachinesOnSite!$E$4:$E$1048576

Sheet User Input
A1: Colour | B1: Description | E1: From the Machine spec library acquired from the mine-site | J1: From the Machine spec library acquired from the mine-site | O1: When information about the machine is unavaliable
B2: Drop Down menu | E2: Category | F2: Enter Value | G2: Values | J2: Category | K2: Enter Value | L2: Values | O2: Category | P2: Enter Value | Q2: Value
B3: Data based on selection | E3: Fuse | F3: Safety current factor (%) | G3: 25 | H3: Step 1: Select Option | J3: Fuse | K3: Safety current factor (%) | L3: 25 | O3: System | P3: Voltage (V) | Q3: 16 | R3: Step 1: Select Option
O4: Circuit | P4: Starter circuit | Q4: 24 | R4: Step 2: Select Option
E5: Machine | F5: Model | G5: 637G | H5: Step 2: Select Option | J5: Machine | K5: Model | L5: B45E | P5: Cranking time (s) | Q5: 5 | R5: Step 3: Select Option
F7: Boundary Conditions | K7: Boundary Conditions | O7: Alternator /DCDC | P7: Alternator Voltage (V) | Q7: 24 | R7: Step 4: Select Option
A8: Author | B8: Blossom Fernandez | E8: System | F8: Minimum battery voltage for a 24V system (V) (3% voltage drop) | G8: =INDEX(MachinesOnSite!$I$1:$I$1903, MATCH(G5, MachinesOnSite!$D$1:$D$1903, 0)) -> 16.48 | J8: System | K8: Minimum battery voltage for a 24V system (V) | L8: =INDEX(MachinesOnSite!$I$1:$I$1903, MATCH(L5, MachinesOnSite!$D$1:$D$1903, 0)) -> 16.48 | P8: Alternator Continuous Current (A) | Q8: 100 | R8: Step 5: Select Option
F9: Minimum battery voltage received by the starter motor (V) | G9: =INDEX(MachinesOnSite!$N$1:$N$1903, MATCH($G$5, MachinesOnSite!$D$1:$D$1903, 0)) -> 16 | K9: Minimum battery voltage received by the starter motor (V) | L9: =INDEX(MachinesOnSite!$N$1:$N$1903, MATCH($G$5, MachinesOnSite!$D$1:$D$1903, 0)) -> 16
E10: Starter Motor | F10: Output/Mechanical power (kW) | G10: =INDEX(MachinesOnSite!$O$1:$O$1903, MATCH($G$5, MachinesOnSite!$D$1:$D$1903, 0)) -> 9 | J10: Starter Motor | K10: Output/Mechanical power (kW) | L10: =INDEX(MachinesOnSite!$O$1:$O$1903, MATCH($G$5, MachinesOnSite!$D$1:$D$1903, 0)) -> 9 | O10: Starter Motor | P10: Starter Motor Voltage (V) | Q10: 24 | R10: Step 6: Select Option
F11: Starter motor efficiency during optimum conditions (%) | G11: =INDEX(MachinesOnSite!$P$1:$P$1903, MATCH($G$5, MachinesOnSite!$D$1:$D$1903, 0)) -> 56.25 | K11: Starter motor efficiency during optimum conditions (%) | L11: =INDEX(MachinesOnSite!$P$1:$P$1903, MATCH($G$5, MachinesOnSite!$D$1:$D$1903, 0)) -> 56.25 | P11: Starter Motor Cranking/Peak Current (A) | Q11: 1000 | R11: Step 7: Select Option
F12: Peak current draw cut off value (A) | G12: =INDEX(MachinesOnSite!$Q$1:$Q$1903, MATCH($G$5, MachinesOnSite!$D$1:$D$1903, 0)) -> 1000 | K12: Peak current draw cut off value (A) | L12: =INDEX(MachinesOnSite!$Q$1:$Q$1903, MATCH($G$5, MachinesOnSite!$D$1:$D$1903, 0)) -> 1000
F13: Maximum cranking time based on cables peak current capability (s) | G13: =15/1000 -> 0.015 | K13: Maximum cranking time based on cables peak current capability (s) | L13: 5 | P13: User customisation
O14: Cable | P14: Cable Type | Q14: Two Single Core | R14: Step 8: Select Option
F15: Results for what is measured / Present | K15: Results for what is measured / Present | P15: Insulation Type | Q15: X-90 , XLPE | R15: Step 9: Select Option
E16: Machine | F16: Manufacturer | G16: =INDEX(MachinesOnSite!$C$1:$C$1903, MATCH(G5, MachinesOnSite!$D$1:$D$1903, 0)) -> Caterpillar | J16: Machine | K16: Manufacturer | L16: =INDEX(MachinesOnSite!$C$1:$C$1903, MATCH(L5, MachinesOnSite!$D$1:$D$1903, 0)) -> Bell | P16: Location type | Q16: Enclosed | R16: Step 10: Select Option
E17: Battery | F17: What is the measured battery voltage during cranking (V)? | G17: =INDEX(MachinesOnSite!$W$1:$W$1903, MATCH(G5, MachinesOnSite!$D$1:$D$1903, 0)) -> 0 | J17: Battery | K17: What is the measured battery voltage during cranking (V)? | L17: =INDEX(MachinesOnSite!$W$1:$W$1903, MATCH(L5, MachinesOnSite!$D$1:$D$1903, 0)) -> 20 | P17: Cable Size (mm2) | Q17: 120 | R17: Step 11: Select Option
F18: What is the measured cranking time (s)? | G18: =INDEX(MachinesOnSite!$X$1:$X$1903, MATCH(G5, MachinesOnSite!$D$1:$D$1903, 0)) -> 0 | K18: What is the measured cranking time (s)? | L18: =INDEX(MachinesOnSite!$X$1:$X$1903, MATCH(L5, MachinesOnSite!$D$1:$D$1903, 0)) -> 3 | P18: Operating Temperature (°C) | Q18: 90 | R18: Step 12: Select Option
F19: Should the battery be replaced due to low voltage or longer cranking time? | G19: =IF(OR(G16 < G8, G17 < G13), "YES", "NO") -> YES | K19: Should the battery be replaced due to low voltage or longer cranking time? | L19: =IF(OR(L16 < L8, L17 < L13), "YES", "NO") -> NO | P19: In rush current noticed/ allowed (A) | Q19: 1000 | R19: Step 13: Select Option
E20: Starter Motor | F20: Starter Motor Peak/Cranking Current (A) | G20: =INDEX(MachinesOnSite!$T$2:$T$1903, MATCH($G$5, MachinesOnSite!$D$2:$D$1903, 0)) -> 0 | J20: Starter Motor | K20: Starter Motor Peak/Cranking Current (A) | L20: =INDEX(MachinesOnSite!$T$2:$T$1903, MATCH($G$5, MachinesOnSite!$D$2:$D$1903, 0)) -> 0 | P20: Voltage drop (%) | Q20: 3
F21: Is the cranking current less than the max value for the machine? | G21: =IF(OR(G20="", G20="TBC"), "Data Unavailable", IF(G20<G12, "YES", "NO")) -> YES | K21: Is the cranking current less than the max value for the machine? | L21: =IF(OR(L20="", L20="TBC"), "Data Unavailable", IF(L20<L12, "YES", "NO")) -> YES | O21: Fuse | P21: Safety current factor (%) | Q21: 125
F22: Should the starter motor be replaced due to high inrush demand? | G22: =IF(G21= "NO", "YES", "NO") -> NO | K22: Should the starter motor be replaced due to high inrush demand? | L22: =IF(L21= "NO", "YES", "NO") -> NO
E23: Alternator | F23: Alternator Continuous current (A) | G23: =INDEX(MachinesOnSite!$Z$2:$Z$1903, MATCH($G$5, MachinesOnSite!$D$2:$D$1903, 0)) -> 150 | J23: Alternator | K23: Alternator Continuous current (A) | L23: =INDEX(MachinesOnSite!$Z$2:$Z$1903, MATCH($G$5, MachinesOnSite!$D$2:$D$1903, 0)) -> 150 | P23: Results for what is recommended
E24: Cable | F24: Cable Type | G24: =INDEX(MachinesOnSite!$AD$2:$AD$1903, MATCH($G$5, MachinesOnSite!$D$2:$D$1903, 0)) -> 0 | J24: Cable | K24: Cable Type | L24: =INDEX(MachinesOnSite!$AD$2:$AD$1903, MATCH($G$5, MachinesOnSite!$D$2:$D$1903, 0)) -> 0 | O24: Cable | P24: Cable continuous current (A) | Q24: =VLOOKUP(Q17,Cable_Capacity!F2:G5,2,FALSE) -> 389 | R24: =IFERROR(VLOOKUP(Q17,Cable_Capacity!F2:G5,2,FALSE), IFERROR(VLOOKUP(Q16,Cable_Capacity!F2:G5,2,FALSE), VLOOKUP(Q18,Cable_Capacity!F2:G5,2,FALSE) ) ) -> 389
F25: Present Cable Size (mm2) | G25: =INDEX(MachinesOnSite!$AE$2:$AE$1903, MATCH($G$5, MachinesOnSite!$D$2:$D$1903, 0)) -> 70 | K25: Present Cable Size (mm2) | L25: =INDEX(MachinesOnSite!$AE$2:$AE$1903, MATCH($G$5, MachinesOnSite!$D$2:$D$1903, 0)) -> 70 | P25: Can the cable handle the continous current demand? | Q25: =IF((Q8<=Q24),"YES","NO") -> YES
F26: Operating Temperature (°C) | G26: =INDEX(MachinesOnSite!AF2:AF1903, MATCH($G$5, MachinesOnSite!$D$2:$D$1903, 0)) -> 0 | K26: Operating Temperature (°C) | L26: =INDEX(MachinesOnSite!AK2:AK1903, MATCH($G$5, MachinesOnSite!$D$2:$D$1903, 0)) -> 0 | P26: Peak/short circuit current carrying capability (A) | Q26: =ROUND(Q28*Q17/SQRT(Q5),0) -> #N/A
F27: Cable continuous current (A) | G27: =INDEX(MachinesOnSite!$AG$2:$AG$1903, MATCH($G$5, MachinesOnSite!$D$2:$D$1903, 0)) -> 314 | K27: Cable continuous current (A) | L27: =INDEX(MachinesOnSite!$AG$2:$AG$1903, MATCH($G$5, MachinesOnSite!$D$2:$D$1903, 0)) -> 314 | P27: Can the cable handle the in-rush current demand? | Q27: =IF((Q11<Q26),"YES","NO") -> #N/A
F28: Can the Present cable handle the continuous current demand? | G28: =IF(OR(AND(G23="", G27=""), AND(G23="TBC", G27="TBC")), "Data Unavailable for Calculation", IF(G23<=G27, "YES", "NO")) -> YES | K28: Can the Present cable handle the continuous current demand? | L28: =IF(OR(AND(L23="", L27=""), AND(L23="TBC", L27="TBC")), "Data Unavailable for Calculation", IF(L23<=L27, "YES", "NO")) -> YES | P28: K factor (for copper) | Q28: =VLOOKUP($Q$14,Copper_K_Factor!A3:B8,2,FALSE) -> #N/A
F29: K factor (for copper) | G29: =INDEX(Copper_K_Factor!B3:B20, MATCH(G24, Copper_K_Factor!A3:A20, 0)) -> #N/A | K29: K factor (for copper) | L29: =INDEX(Copper_K_Factor!G3:G20, MATCH(L24, Copper_K_Factor!F3:F20, 0)) -> #N/A | P29: I2t calculated for allowed in-rush current (A) | Q29: =Q19*Q19*Q5 -> 5000000
F30: Short circuit current carrying capability (A) (time <= 5 s) | G30: =ROUND((G29*G25/SQRT(G13)),0) -> #N/A | K30: Peak/short circuit current carrying capability (A) (time <= 5 s) | L30: =ROUND((L29*L25/SQRT(L13)),0) -> #N/A | P30: Cable resistance (W/km) | Q30: =VLOOKUP(Q17,Cable_Capacity!F2:H5,3,FALSE) -> 0.188
F31: Can the present cable handle the in-rush current demand? | G31: =IF(OR(ISNA(G12), ISNA(G30)), "Data Unavailable for Calculation", IF(OR(G12="", G30=""), "Data Unavailable for Calculation", IF(OR(G12="TBC", G30="TBC"), "Data Unavailable for Calculation", IF(G12 < G30, "YES", "NO" ) ) ) ) -> Data Unavailable for Calculation | K31: Can the present cable handle the in-rush current demand? | L31: =IF(OR(ISNA(L12), ISNA(L30)), "Data Unavailable for Calculation", IF(OR(L12="", L30=""), "Data Unavailable for Calculation", IF(OR(L12="TBC", L30="TBC"), "Data Unavailable for Calculation", IF(L12 < L30, "YES", "NO" ) ) ) ) -> Data Unavailable for Calculation | P31: Cable Length for 3% voltage drop (m) | Q31: =ROUND((Q20*1000*Q3)/(Q24*2*Q30*100), 1) -> 3.3
F32: I2t calculated for allowed in-rush current (A) | G32: =IF(G1<=1000, (G12*G12*G18)) -> 0 | K32: I2t calculated for allowed in-rush current (A) | L32: =IF(L1<=1000, (L12*L12*L18)) -> 3000000
F33: Cable resistance (W/km) | G33: =VLOOKUP(G25,Cable_Capacity!F2:H5,3,FALSE) -> 0.327 | K33: Cable resistance (W/km) | L33: =VLOOKUP(L25,Cable_Capacity!K2:M5,3,FALSE) -> #N/A | O33: Fuse | P33: Current rating (A) | Q33: =IF(Q8<=Q24,((Q21/100)*Q24)) -> 486.25
F34: Cable Length (m) | G34: =INDEX(MachinesOnSite!$AI$2:$AI$1903, MATCH($G$5, MachinesOnSite!$D$2:$D$1903, 0)) -> 0 | K34: Cable Length (m) | L34: =INDEX(MachinesOnSite!$AI$2:$AI$1903, MATCH($G$5, MachinesOnSite!$D$2:$D$1903, 0)) -> 0 | P34: Closet match for the fusing rating (A) | Q34: {=INDEX(Fuse_Library!Q19:Q1997,MATCH(MIN(ABS(Fuse_Library!Q19:Q1997-Q33)),ABS(Fuse_Library!Q19:Q1997-Q33),0))} -> 0
F35: Voltage drop (%) | G35: =((G27*G34*2*G33/1000)*100)/G17 -> #DIV/0! | K35: Voltage drop (%) | L35: =((L27*L34*2*L33/1000)*100)/L17 -> #N/A | P35: I2t (A2s) available | Q35: {=IFERROR(INDEX(_xlfn._xlws.FILTER(Fuse_Library!F2:F1997, (Fuse_Library!E2:E1997 = Q34) * (Fuse_Library!F2:F1997 > Q29)), 1), "NO MATCH")} -> Zcase
P36: Manufacturer | Q36: =IFERROR(INDEX(Fuse_Library!B2:B1997, MATCH(Q35, Fuse_Library!$F$2:$F$1997, 0)), "NO MATCH") -> rated current
F37: Results for what is recommended based on Time Characteristics graph | K37: Results for what is recommended based on Time Characteristics graph | P37: Description | Q37: =IFERROR(INDEX(Fuse_Library!C2:C1997, MATCH(Q35, Fuse_Library!$F$2:$F$1997, 0)),"NO MATCH") -> 0
E38: Category | F38: Enter Value | G38: Values | J38: Category | K38: Enter Value | L38: Values | P38: Part # | Q38: =IFERROR(INDEX(Fuse_Library!D2:D1997,MATCH(Q35,Fuse_Library!$F$2:$F$1997,0)),"NO MATCH") -> De rating factor
E39: Fuse | F39: Current rating (A) based on continuous current demand. | G39: =IF(G23<=G27,(((G3+100)/100)*G23)) -> 187.5 | J39: Fuse | K39: Current rating (A) based on continuous current demand. | L39: =IF(L23<=L27,(((L3+100)/100)*L23)) -> 187.5 | P39: Time it can withstand 1000A current (s) | Q39: =IFERROR(INDEX(Fuse_Library!H2:H1997, MATCH(Q35, Fuse_Library!$F$2:$F$1997, 0)),"NO MATCH") -> 0
F40: Closet match for the fusing rating (A) | G40: {=IFERROR(INDEX(Fuse_Library!M2:M25, MATCH(MIN(ABS(Fuse_Library!M2:M25-G39)), ABS(Fuse_Library!M2:M25-G39), 0)), "Data Unavailable")} -> 175 | K40: Closet match for the fusing rating (A) | L40: {=IFERROR(INDEX(Fuse_Library!R2:R25, MATCH(MIN(ABS(Fuse_Library!R2:R25-L39)), ABS(Fuse_Library!R2:R25-L39), 0)), "Data Unavailable")} -> 0 | P40: Interrupting rating (A @V) | Q40: =IFERROR((INDEX(Fuse_Library!J2:J1997, MATCH(Q35, Fuse_Library!$F$2:$F$1997, 0))),"NO MATCH") -> 0
F41: Is the fuse size available? If not, what is the next fuse size available? | G41: =IF(ISNUMBER(MATCH(G40, Fuse_Library!E2:E30, 0)), "YES", MIN(Fuse_Library!E2:E30)) -> 300 | K41: Is the fuse size available? If not, what is the next fuse size available? | L41: =IF(ISNUMBER(MATCH(L40, Fuse_Library!J2:J30, 0)), "YES", MIN(Fuse_Library!J2:J30)) -> 0 | P41: Website link | Q41: =HYPERLINK(IFERROR((INDEX(Fuse_Library!L2:L1997, MATCH(Q35, Fuse_Library!$F$2:$F$1997, 0))), "NO MATCH"))
...

Sheet Results
A1: # | B1: =MachinesOnSite!B2 -> Site | C1: Manufacturer | D1: Model | E1: Suggested Fuse (A) Size | F1: Fuse open circuit current (measured) | G1: Cranking Current (A) | H1: Required cranking time (s) | I1: Littelfuse, Fuse part # | J1: LittleFuse, Fuse Holder part # | K1: GB Part # | L1: Time value from the graph (s) | M1: Does the fuse match the requirement? | N1: Parallel configuration (if required) | O1: I2t (A2s) required | P1: 40 DegC Operating temp current (A) (typical derating) | Q1: Alternator current (A) | R1: Continuous current < = derating current
A2: 0 | B2: Select | C2: Select | D2: Select | E2: Select | F2: Select | G2: Select | H2: Select | I2: Select | J2: Select | K2: Select | L2: Select | M2: Select | N2: Select
A3: =1+A2 -> 1 | B3: =MachinesOnSite!B4 -> SEE Civil Pad, Tailings Dam, Cadia | C3: =MachinesOnSite!C4 -> Ammann | D3: =MachinesOnSite!D4 -> 18T_Padfoot
A4: =1+A3 -> 2 | B4: =MachinesOnSite!B5 -> SEE Civil Pad, Tailings Dam, Cadia | C4: =MachinesOnSite!C5 -> Bell | D4: =MachinesOnSite!D5 -> B45E
A5: =1+A4 -> 3 | B5: =MachinesOnSite!B6 -> SEE Civil Pad, Tailings Dam, Cadia | C5: =MachinesOnSite!C6 -> Bomag | D5: =MachinesOnSite!D6 -> 26T_Padfoot
A6: =1+A5 -> 4 | B6: =MachinesOnSite!B7 -> SEE Civil Pad, Tailings Dam, Cadia | C6: =MachinesOnSite!C7 -> Bomag | D6: =MachinesOnSite!D7 -> 26T_Smoothdrum
A7: =1+A6 -> 5 | B7: =MachinesOnSite!B8 -> SEE Civil Pad, Tailings Dam, Cadia | C7: =MachinesOnSite!C8 -> Caterpillar | D7: =MachinesOnSite!D8 -> 773
A8: =1+A7 -> 6 | B8: =MachinesOnSite!B9 -> SEE Civil Pad, Tailings Dam, Cadia | C8: =MachinesOnSite!C9 -> Caterpillar | D8: =MachinesOnSite!D9 -> 988
A9: =1+A8 -> 7 | B9: =MachinesOnSite!B10 -> SEE Civil Pad, Tailings Dam, Cadia | C9: =MachinesOnSite!C10 -> Caterpillar | D9: =MachinesOnSite!D10 -> 14H
A10: =1+A9 -> 8 | B10: =MachinesOnSite!B11 -> SEE Civil Pad, Tailings Dam, Cadia | C10: =MachinesOnSite!C11 -> Caterpillar | D10: =MachinesOnSite!D11 -> 14M
A11: =1+A10 -> 9 | B11: =MachinesOnSite!B12 -> SEE Civil Pad, Tailings Dam, Cadia | C11: =MachinesOnSite!C12 -> Caterpillar | D11: =MachinesOnSite!D12 -> 16M
A12: =1+A11 -> 10 | B12: =MachinesOnSite!B13 -> SEE Civil Pad, Tailings Dam, Cadia | C12: =MachinesOnSite!C13 -> Caterpillar | D12: =MachinesOnSite!D13 -> 18T_smoothdrum /CS19 /CS78B
A13: =1+A12 -> 11 | B13: =MachinesOnSite!B14 -> SEE Civil Pad, Tailings Dam, Cadia | C13: =MachinesOnSite!C14 -> Caterpillar | D13: =MachinesOnSite!D14 -> 36T /336 -Tier 4 / Stage V
A14: =1+A13 -> 12 | B14: =MachinesOnSite!B15 -> SEE Civil Pad, Tailings Dam, Cadia | C14: =MachinesOnSite!C15 -> Caterpillar | D14: =MachinesOnSite!D15 -> 30 T/ 330 - Tier 4 / tge
... A37: =1+A36 -> 35 | B37: =MachinesOnSite!B38 -> SEE Civil Pad, Tailings Dam, Cadia | C37: =MachinesOnSite!C38 -> Komatsu | D37: =MachinesOnSite!D38 -> HD465
A38: =1+A37 -> 36 | B38: =MachinesOnSite!B39 -> SEE Civil Pad, Tailings Dam, Cadia | C38: =MachinesOnSite!C39 -> Komatsu | D38: =MachinesOnSite!D39 -> WA1200 | O38: =G38*G38*H38 -> 0 | P38: 207 | Q38: N/A | R38: yes, 200 cont
A39: =1+A38 -> 37 | B39: =MachinesOnSite!B40 -> 0 | C39: =MachinesOnSite!C40 -> 0 | D39: =MachinesOnSite!D40 -> MD6250
A40: =1+A39 -> 38 | B40: =MachinesOnSite!B41 -> 0 | C40: =MachinesOnSite!C41 -> 0 | D40: =MachinesOnSite!D41 -> 0
A41: =1+A40 -> 39 | B41: =MachinesOnSite!B42 -> 0 | C41: =MachinesOnSite!C42 -> 0 | D41: =MachinesOnSite!D42 -> 0
A42: =1+A41 -> 40 | B42: =MachinesOnSite!B43 -> 0 | C42: =MachinesOnSite!C43 -> 0 | D42: =MachinesOnSite!D43 -> 0
A43: =1+A42 -> 41 | B43: =MachinesOnSite!B44 -> 0 | C43: =MachinesOnSite!C44 -> 0 | D43: =MachinesOnSite!D44 -> 0
A44: =1+A43 -> 42 | B44: =MachinesOnSite!B45 -> 0 | C44: =MachinesOnSite!C45 -> 0 | D44: =MachinesOnSite!D45 -> 0
A45: =1+A44 -> 43 | B45: =MachinesOnSite!B46 -> 0 | C45: =MachinesOnSite!C46 -> 0 | D45: =MachinesOnSite!D46 -> 0
A46: =1+A45 -> 44 | B46: =MachinesOnSite!B47 -> 0 | C46: =MachinesOnSite!C47 -> 0 | D46: =MachinesOnSite!D47 -> 0
A47: =1+A46 -> 45 | B47: =MachinesOnSite!B48 -> 0 | C47: =MachinesOnSite!C48 -> 0 | D47: =MachinesOnSite!D48 -> 0
A48: =1+A47 -> 46 | B48: =MachinesOnSite!B49 -> 0 | C48: =MachinesOnSite!C49 -> 0 | D48: =MachinesOnSite!D49 -> 0
A49: =1+A48 -> 47 | B49: =MachinesOnSite!B50 -> 0 | C49: =MachinesOnSite!C50 -> 0 | D49: =MachinesOnSite!D50 -> 0
A50: =1+A49 -> 48 | B50: =MachinesOnSite!B51 -> 0 | C50: =MachinesOnSite!C51 -> 0 | D50: =MachinesOnSite!D51 -> 0
... A131: =1+A130 -> 129 | B131: =MachinesOnSite!B132 -> 0 | C131: =MachinesOnSite!C132 -> 0 | D131: =MachinesOnSite!D132 -> 0
A132: =1+A131 -> 130 | B132: =MachinesOnSite!B133 -> 0 | C132: =MachinesOnSite!C133 -> 0 | D132: =MachinesOnSite!D133 -> 0 | O132: =G132*G132*H132 -> 0 | P132: 302 | S132: 3 | T132: 450
A133: 3 | C133: Catepillar | D133: D10T | E133: 500 | F133: 500 | G133: 1000 | H133: 5 | I133: 0298500.ZXH | J133: 8800 |4 | L133: 10 | M133: =L133>=H133 -> TRUE | N133: N/A | O133: =G133*G133*H133 -> 5000000 | P133: 302 | S133: 2 | T133: 450
A134: 4 | C134: Komatsu | D134: 155 | E134: 500 | F134: 400 | G134: 1000 | H134: 5 | I134: 0298500.ZXH | J134: 8800 |4 | L134: 10 | M134: =L134>=H134 -> TRUE | N134: N/A | O134: =G134*G134*H134 -> 5000000 | P134: 302 | S134: 5 | T134: 450
A135: 5 | C135: Komatsu | D135: 375 | E135: 500 | F135: 750 | G135: 1000 | H135: 5 | I135: 0298500.ZXH | J135: 8800 |4 | L135: 10 | M135: =L135>=H135 -> TRUE | N135: N/A | O135: =G135*G135*H135 -> 5000000 | P135: 302 | S135: 1 | T135: 450
A136: 6 | C136: Hitachi | D136: 120T | E136: 500 | F136: 650 | G136: 1000 | H136: 5 | I136: 0298500.ZXH | J136: 8800 |4 | L136: 10 | M136: =L136>=H136 -> TRUE | N136: N/A | O136: =G136*G136*H136 -> 5000000 | P136: 302 | S136: 1 | T136: 450
A137: 7 | C137: Catepillar | D137: 14M | E137: 500 | F137: 350 | G137: 1000 | H137: 5 | I137: 0298500.ZXH | J137: 8800 |4 | L137: 10 | M137: =L137>=H137 -> TRUE | N137: N/A | O137: =G137*G137*H137 -> 5000000 | P137: 302 | S137: 3 | T137: 450
A138: =1+A137 -> 8 | B138: =MachinesOnSite!B139 -> 0 | C138: =MachinesOnSite!C139 -> 0 | D138: =MachinesOnSite!D139 -> 0 | O138: =G138*G138*H138 -> 0 | P138: 302 | S138: 3 | T138: 450
A139: =1+A138 -> 9 | B139: =MachinesOnSite!B140 -> 0 | C139: =MachinesOnSite!C140 -> 0 | D139: =MachinesOnSite!D140 -> 0 | S139: 2 | T139: 450
A140: =1+A139 -> 10 | B140: =MachinesOnSite!B141 -> 0 | C140: =MachinesOnSite!C141 -> 0 | D140: =MachinesOnSite!D141 -> 0 | S140: 6 | T140: 450
A141: 9 | C141: Catepillar | D141: 992K | E141: 500 | F141: 950 | G141: 1000 | H141: 6 | I141: 0298500.ZXH | J141: 8800 |4 | L141: 10 | M141: =L141>=H141 -> TRUE | N141: N/A | O141: =G141*G141*H141 -> 6000000 | P141: 302 | S141: 5
A142: 10 | C142: Catepillar | D142: D11 | E142: 500 | F142: 750 | G142: 1000 | H142: 5 | I142: 0298500.ZXH | J142: 8800 |4 | L142: 10 | M142: =L142>=H142 -> TRUE | N142: N/A | O142: =G142*G142*H142 -> 5000000 | P142: 302 | S142: 5
...

Sheet MachinesOnSite
A1: Info | I1: Battery | L1: Fuse | M1: Starter Motor Peak Current (A) | Z1: Alternator | AD1: Cable
A2: # | B2: Site | C2: Manufcturer | D2: Model | E2: TYPE | F2: Category | G2: Engine | H2: Electrical System (V) | I2: Minimum battery Voltage (V) | J2: Configuration | K2: 5 sec discharge | L2: Fuse Installed (A) | M2: TyPe | N2: Cut off Voltage (V) | O2: Power at Cut off voltage (kW) | P2: Efficiency (%) | Q2: Peak current cut off(A) from power & eff calcukatuiion | R2: Inrush Current (A) Measured | S2: Inrush current time (s) | T2: Peak continuous current during cranking (A) | U2: No of Motors | V2: type | W2: Cranking Voltge (V) measured | X2: Cranking time (s) Measured | Y2: Cranking time (s)required | Z2: Alternator Continuous Current (A) | AA2: Type | AB2: Voltage (v) | AC2: No of Alternators | AD2: Cable Type | AE2: Cable Size(mm2) | AF2: Operating temperature (DegC) | AG2: Continuous Current (A) | AH2: Peak (A) | AI2: Cable Length (m) | AJ2: Link
A3: 0 | B3: Select | C3: Select | D3: Select | H3: 1
A4: =1+A3 -> 1 | B4: SEE Civil Pad, Tailings Dam, Cadia | C4: Ammann | D4: 18T_Padfoot | F4: Roller | I4: =IF(H4=24,(16+(16*0.03))," ") | N4: =IF(I4=16.48,16," ") | P4: 56.25 | Q4: =ROUNDUP(((O4*1000*100)/(N4*P4)),0) -> #VALUE! | Y4: =IF(X4 <5, 5, X4) -> 5
A5: =1+A4 -> 2 | B5: SEE Civil Pad, Tailings Dam, Cadia | C5: Bell | D5: B45E | F5: Truck | H5: 24 | I5: =IF(H5=24,(16+(16*0.03))," ") -> 16.48 | J5: 12V x2, 975CCA,75AH | K5: =75*3600/5 -> 54000 | L5: 1000 | N5: =IF(I5=16.48,16," ") -> 16 | O5: 4.5 | P5: 56.25 | Q5: =ROUNDUP(((O5*1000*100)/(N5*P5)),0) -> 500 | R5: 330 | T5: 200 | U5: 1 | W5: 20 | X5: 3 | Y5: =IF(X5 <5, 5, X5) -> 5 | Z5: 80 | AB5: 1 | AD5: OEM Wiring | AE5: 70 | AF5: 60 | AG5: 314 | AI5: 6
A6: =1+A5 -> 3 | B6: SEE Civil Pad, Tailings Dam, Cadia | C6: Bomag | D6: 26T_Padfoot | F6: Roller | I6: =IF(H6=24,(16+(16*0.03))," ") | N6: =IF(I6=16.48,16," ") | P6: 56.25 | Q6: =ROUNDUP(((O6*1000*100)/(N6*P6)),0) -> #VALUE! | Y6: =IF(X6 <5, 5, X6) -> 5
A7: =1+A6 -> 4 | B7: SEE Civil Pad, Tailings Dam, Cadia | C7: Bomag | D7: 26T_Smoothdrum | F7: Roller | I7: =IF(H7=24,(16+(16*0.03))," ") | N7: =IF(I7=16.48,16," ") | P7: 56.25 | Q7: =ROUNDUP(((O7*1000*100)/(N7*P7)),0) -> #VALUE! | Y7: =IF(X7 <5, 5, X7) -> 5
A8: =1+A7 -> 5 | B8: SEE Civil Pad, Tailings Dam, Cadia | C8: Caterpillar | D8: 773 | F8: Watercart | I8: =IF(H8=24,(16+(16*0.03))," ") | M8: 6V-0885 | N8: =IF(I8=16.48,16," ") | O8: 9 | P8: 56.25 | Q8: =ROUNDUP(((O8*1000*100)/(N8*P8)),0) -> #VALUE! | Y8: =IF(X8 <5, 5, X8) -> 5 | Z8: 115 | AA8: CAT469-4705
A9: =1+A8 -> 6 | B9: SEE Civil Pad, Tailings Dam, Cadia | C9: Caterpillar | D9: 988 | F9: Loader | I9: =IF(H9=24,(16+(16*0.03))," ") | M9: 1990366 (42MT) | N9: =IF(I9=16.48,16," ") | O9: 9 | P9: 56.25 | Q9: =ROUNDUP(((O9*1000*100)/(N9*P9)),0) -> #VALUE! | Y9: =IF(X9 <5, 5, X9) -> 5
A10: =1+A9 -> 7 | B10: SEE Civil Pad, Tailings Dam, Cadia | C10: Caterpillar | D10: 14H | F10: Grader | I10: =IF(H10=24,(16+(16*0.03))," ") | M10: 10R-0400 (39MT) | N10: =IF(I10=16.48,16," ") | O10: 7.3 | P10: 56.25 | Q10: =ROUNDUP(((O10*1000*100)/(N10*P10)),0) -> #VALUE! | Y10: =IF(X10 <5, 5, X10) -> 5
A11: =1+A10 -> 8 | B11: SEE Civil Pad, Tailings Dam, Cadia | C11: Caterpillar | D11: 14M | F11: Grader | H11: 24 | I11: =IF(H11=24,(16+(16*0.03))," ") -> 16.48 | J11: 12V x2, 1125CCA, 145AH | K11: =145*3600/5 -> 104400 | L11: 100 | M11: 10R-0400 | N11: =IF(I11=16.48,16," ") -> 16 | O11: 7.3 | P11: 56.25 | Q11: =ROUNDUP(((O11*1000*100)/(N11*P11)),0) -> 812 | R11: 450 | T11: 350 | U11: 1 | V11: CAT | W11: 21 | X11: 3 | Y11: =IF(X11 <5, 5, X11) -> 5 | Z11: 150 | AA11: 272-1889 | AB11: 1 | AD11: Weldflex | AE11: 70 | AF11: 60 | AG11: 314 | AI11: 4
A12: =1+A11 -> 9 | B12: SEE Civil Pad, Tailings Dam, Cadia | C12: Caterpillar | D12: 16M | F12: Grader | I12: =IF(H12=24,(16+(16*0.03))," ") | M12: 10R-0400 | N12: =IF(I12=16.48,16," ") | O12: 7.3 | P12: 56.25 | Q12: =ROUNDUP(((O12*1000*100)/(N12*P12)),0) -> #VALUE! | Y12: =IF(X12 <5, 5, X12) -> 5
A13: =1+A12 -> 10 | B13: SEE Civil Pad, Tailings Dam, Cadia | C13: Caterpillar | D13: 18T_smoothdrum /CS19 /CS78B | F13: Roller | I13: =IF(H13=24,(16+(16*0.03))," ") | M13: 590-4756 | N13: =IF(I13=16.48,16," ") | O13: 4.5 | P13: 56.25 | Q13: =ROUNDUP(((O13*1000*100)/(N13*P13)),0) -> #VALUE! | Y13: =IF(X13 <5, 5, X13) -> 5
A14: =1+A13 -> 11 | B14: SEE Civil Pad, Tailings Dam, Cadia | C14: Caterpillar | D14: 36T /336 -Tier 4 / Stage V | F14: Excavator | I14: =IF(H14=24,(16+(16*0.03))," ") | M14: 488-2807 | N14: =IF(I14=16.48,16," ") | O14: 7.8 | P14: 56.25 | Q14: =ROUNDUP(((O14*1000*100)/(N14*P14)),0) -> #VALUE! | Y14: =IF(X14 <5, 5, X14) -> 5
A15: =1+A14 -> 12 | B15: SEE Civil Pad, Tailings Dam, Cadia | C15: Caterpillar | D15: 30 T/ 330 - Tier 4 / tge | F15: Medium Extractor | G15: C7.1 | H15: 24 | I15: =IF(H15=24,(16+(16*0.03))," ") -> 16.48 | J15: 12 x2, 1000 CC | M15: 488-2807 | N15: =IF(I15=16.48,16," ") -> 16 | O15: 7.8 | P15: 56.25 | Q15: =ROUNDUP(((O15*1000*100)/(N15*P15)),0) -> 867 | Y15: =IF(X15 <5, 5, X15) -> 5 | Z15: 115 | AJ15: http://www.ct.co/en_U/product/new/equipent/Extractor/Medium-Extractor/15969757.htl
A16: =1+A15 -> 13 | B16: Newmont | C16: Caterpillar | D16: 637G | F16: Scraper | G16: C18 | H16: 24 | I16: =IF(H16=24,(16+(16*0.03))," ") -> 16.48 | J16: 12 x4, 1400 CC | L16: N/A | M16: DELCO DD | N16: =IF(I16=16.48,16," ") -> 16 | O16: 9 | P16: 56.25 | Q16: =ROUNDUP(((O16*1000*100)/(N16*P16)),0) -> 1000 | Y16: =IF(X16 <5, 5, X16) -> 5 | Z16: 150 | AE16: 70 | AG16: 314 | AJ16: http://www.ct.co/en_U/product/new/equipent/wheel-trctor-Scraper/open-bowl-Scraper/119362.htl
A17: =1+A16 -> 14 | B17: SEE Civil Pad, Tailings Dam, Cadia | C17: Caterpillar | D17: 49T /349 | F17: Excavator | I17: =IF(H17=24,(16+(16*0.03))," ") | M17: 20R-1312 | N17: =IF(I17=16.48,16," ") | O17: 9 | P17: 56.25 | Q17: =ROUNDUP(((O17*1000*100)/(N17*P17)),0) -> #VALUE! | Y17: =IF(X17 <5, 5, X17) -> 5
A18: =1+A17 -> 15 | B18: SEE Civil Pad, Tailings Dam, Cadia | C18: Caterpillar | D18: Backhoe | F18: Loader | I18: =IF(H18=24,(16+(16*0.03))," ") | M18: 0R-4316 | N18: =IF(I18=16.48,16," ") | O18: 2.7 | P18: 56.25 | Q18: =ROUNDUP(((O18*1000*100)/(N18*P18)),0) -> #VALUE! | Y18: =IF(X18 <5, 5, X18) -> 5
A19: =1+A18 -> 16 | B19: SEE Civil Pad, Tailings Dam, Cadia | C19: Caterpillar | D19: 777 (07) | E19: Surface | F19: Off-Highwy truck | G19: C32B | H19: 24 | I19: =IF(H19=24,(16+(16*0.03))," ") -> 16.48 | J19: 12v x4,700CCA, 100AH | K19: =100*3600/5 -> 72000 | L19: 1000 | M19: 10R-9816 (50MT) | N19: =IF(I19=16.48,16," ") -> 16 | O19: 9 | P19: =O19*1000*100/(N19*Q19) -> 56.25 | Q19: 1000 | R19: 2000 | T19: 1200 | U19: 2 | W19: 18 | X19: 5 | Y19: =IF(X19 <5, 5, X19) -> 5 | Z19: 150 | AB19: 1 | AD19: Weldflex | AE19: 95 | AF19: 40 | AG19: 375 | AH19: 1200 | AI19: 12 | AJ19: http://www.ct.co/en_U/product/new/equipent/off-highwy-truck/off-highwy-truck/115560.htl
A20: =1+A19 -> 17 | B20: SEE Civil Pad, Tailings Dam, Cadia | C20: Caterpillar | D20: 793F | E20: Surface | F20: Mining Truck | G20: C175-17 | H20: 24 | I20: =IF(H20=24,(16+(16*0.03))," ") -> 16.48 | J20: 12v x4, 1300CCA, 210AH | K20: =210*3600/5 -> 151200 | L20: 1000 | M20: 20R-1312 (50MT) | N20: =IF(I20=16.48,16," ") -> 16 | O20: 9 | P20: 56.25 | Q20: =ROUNDUP(((O20*1000*100)/(N20*P20)),0) -> 1000 | R20: 2000 | T20: 1200 | U20: 2 | W20: 18 | X20: 6 | Y20: =IF(X20 <5, 5, X20) -> 6 | Z20: 150 | AB20: 1 | AD20: Weldflex | AE20: 120 | AF20: 40 | AG20: 440 | AH20: 1200 | AI20: 8 | AJ20: http://www.ct.co/en_U/product/new/equipent/off-highwy-truck/Mining-truck/18093014.htl
A21: =1+A20 -> 18 | B21: Newmont | C21: Caterpillar | D21: D6/D6 XE | F21: Medium Dozer | G21: C9.3B | H21: 24 | I21: =IF(H21=24,(16+(16*0.03))," ") -> 16.48 | J21: 2x12, 1400CC | M21: 20R-1312 | N21: =IF(I21=16.48,16," ") -> 16 | O21: 9 | P21: 56.25 | Q21: =ROUNDUP(((O21*1000*100)/(N21*P21)),0) -> 1000 | Y21: =IF(X21 <5, 5, X21) -> 5 | Z21: 150 | AJ21: http://www.ct.co/en_U/product/new/equipent/dozer/Medium-dozer/15969751.htl
A22: =1+A21 -> 19 | B22: SEE Civil Pad, Tailings Dam, Cadia | C22: Caterpillar | D22: 992K | E22: Surface | F22: Large Wheel Loder | G22: C32B | H22: 24 | I22: =IF(H22=24,(16+(16*0.03))," ") -> 16.48 | J22: 12v x4, 1000CCA, 150AH | K22: =150*3600/5 -> 108000 | L22: No Fuse installed | M22: 10R-9816 (50MT) | N22: =IF(I22=16.48,16," ") -> 16 | O22: 9 | P22: =O22*1000*100/(N22*Q22) -> 56.25 | Q22: 1000 | R22: 1380 | T22: 950 | U22: 1 | V22: CAT 252-8716 | W22: 20 | X22: 5 | Y22: =IF(X22 <5, 5, X22) -> 5 | Z22: 150 | AB22: 1 | AD22: Weldflex | AE22: 120 | AF22: 60 | AG22: 440 | AH22: 950 | AI22: 12 | AJ22: http://www.ct.co/en_U/product/new/equipent/wheel-loder/lrge-wheel-loder/108700.htl
A23: =1+A22 -> 20 | B23: SEE Civil Pad, Tailings Dam, Cadia | C23: Caterpillar | D23: 994K | F23: Loader | I23: =IF(H23=24,(16+(16*0.03))," ") | M23: 10R-9816 (50MT) | N23: =IF(I23=16.48,16," ") | O23: 9 | P23: 56.25 | Q23: 1000 | Y23: =IF(X23 <5, 5, X23) -> 5
A24: =1+A23 -> 21 | B24: SEE Civil Pad, Tailings Dam, Cadia | C24: Caterpillar | D24: D10T | F24: Dozer | H24: 24 | I24: =IF(H24=24,(16+(16*0.03))," ") -> 16.48 | J24: 12v x2, 1400CCA,200AH | K24: =200*3600/5 -> 144000 | L24: 1000 | M24: 10R-9816 (50MT) | N24: =IF(I24=16.48,16," ") -> 16 | O24: 9 | P24: =O24*1000*100/(N24*Q24) -> 56.25 | Q24: 1000 | R24: 1200 | T24: 500 | U24: 1 | W24: 16 | X24: 5 | Y24: =IF(X24 <5, 5, X24) -> 5 | Z24: 95 | AA24: CAT239-8035 | AD24: Narva | AE24: 70 | AF24: 60 | AG24: 314 | AH24: 500 | AI24: 6
A25: =1+A24 -> 22 | B25: SEE Civil Pad, Tailings Dam, Cadia | C25: Caterpillar | D25: D11 | F25: Dozer | H25: 24 | I25: =IF(H25=24,(16+(16*0.03))," ") -> 16.48 | J25: 12v x2, 1400CCA,200AH | L25: No Fuse installed | M25: Denso | N25: =IF(I25=16.48,16," ") -> 16 | O25: 9 | P25: 56.25 | Q25: =ROUNDUP(((O25*1000*100)/(N25*P25)),0) -> 1000 | R25: 2000 | T25: 750 | U25: 2 | W25: 22 | X25: 5 | Y25: =IF(X25 <5, 5, X25) -> 5 | Z25: 150 | AA25: CAT272-1889 | AB25: 1 | AD25: Weldflex | AE25: 95 | AF25: 60 | AG25: 375 | AH25: 750 | AI25: 6
A26: =1+A25 -> 23 | B26: SEE Civil Pad, Tailings Dam, Cadia | C26: Caterpillar | D26: D6 | F26: Dozer | I26: =IF(H26=24,(16+(16*0.03))," ") | M26: 10R-9816 (50MT) | N26: =IF(I26=16.48,16," ") | O26: 9 | P26: 56.25 | Q26: =ROUNDUP(((O26*1000*100)/(N26*P26)),0) -> #VALUE! | Y26: =IF(X26 <5, 5, X26) -> 5
A27: =1+A26 -> 24 | B27: SEE Civil Pad, Tailings Dam, Cadia | C27: Caterpillar | D27: D8T | F27: Dozer | I27: =IF(H27=24,(16+(16*0.03))," ") | M27: 10R-9816 (50MT) | N27: =IF(I27=16.48,16," ") | O27: 9 | P27: 56.25 | Q27: =ROUNDUP(((O27*1000*100)/(N27*P27)),0) -> #VALUE! | Y27: =IF(X27 <5, 5, X27) -> 5
A28: =1+A27 -> 25 | B28: SEE Civil Pad, Tailings Dam, Cadia | C28: Hitachi | D28: 120T /EX 1200-7 / EX 2000-7 | F28: Excavator | I28: =IF(H28=24,(16+(16*0.03))," ") | J28: 12v x2, 1500CCA, 200AH | L28: No Fuse instlled | M28: RareElectrical | N28: =IF(I28=16.48,16," ") | O28: 7.5 | P28: 56.25 | Q28: =ROUNDUP(((O28*1000*100)/(N28*P28)),0) -> #VALUE! | R28: 2000 | T28: 650 | U28: 1 | W28: 19 | X28: 3 | Y28: =IF(X28 <5, 5, X28) -> 5 | Z28: 140 | AB28: 1 | AD28: OEM Wiring | AE28: 120 | AF28: 60 | AG28: 440 | AH28: 650 | AI28: 8
A29: =1+A28 -> 26 | B29: SEE Civil Pad, Tailings Dam, Cadia | C29: Hitachi | D29: 360T /EX3600-6 | F29: Excavator | I29: =IF(H29=24,(16+(16*0.03))," ") | M29: S04-019PL (276 | N29: =IF(I29=16.48,16," ") | O29: 8.4 | P29: 56.25 | Q29: =ROUNDUP(((O29*1000*100)/(N29*P29)),0) -> #VALUE! | Y29: =IF(X29 <5, 5, X29) -> 5
A30: =1+A29 -> 27 | B30: SEE Civil Pad, Tailings Dam, Cadia | C30: Hitachi | D30: 69T / ZX650H | F30: Excavator | H30: 24 | I30: =IF(H30=24,(16+(16*0.03))," ") -> 16.48 | J30: 2 x 12v,930CA, 147AH | K30: =147*3600/5 -> 105840 | L30: 1000 | N30: =IF(I30=16.48,16," ") -> 16 | P30: 56.25 | Q30: =ROUNDUP(((O30*1000*100)/(N30*P30)),0) -> 0 | R30: 560 | T30: 400 | U30: 1 | W30: 19 | X30: 2 | Y30: =IF(X30 <5, 5, X30) -> 5 | Z30: 50 | AB30: 1 | AD30: Weldflex | AE30: 95 | AF30: 60 | AG30: 375 | AI30: 6
A31: =1+A30 -> 28 | B31: SEE Civil Pad, Tailings Dam, Cadia | C31: Hitachi | D31: 90T / ZX890-5 | F31: Excavator | I31: =IF(H31=24,(16+(16*0.03))," ") | N31: =IF(I31=16.48,16," ") | P31: 56.25 | Q31: =ROUNDUP(((O31*1000*100)/(N31*P31)),0) -> #VALUE! | Y31: =IF(X31 <5, 5, X31) -> 5
A32: =1+A31 -> 29 | B32: SEE Civil Pad, Tailings Dam, Cadia | C32: Hitachi | D32: ZW180 | F32: Loader | I32: =IF(H32=24,(16+(16*0.03))," ") | N32: =IF(I32=16.48,16," ") | P32: 56.25 | Q32: =ROUNDUP(((O32*1000*100)/(N32*P32)),0) -> #VALUE! | Y32: =IF(X32 <5, 5, X32) -> 5
A33: =1+A32 -> 30 | B33: SEE Civil Pad, Tailings Dam, Cadia | C33: Isuzu | D33: FYH300 | F33: Service_Truck | I33: =IF(H33=24,(16+(16*0.03))," ") | M33: S06-058G | N33: =IF(I33=16.48,16," ") | O33: 5 | P33: 56.25 | Q33: =ROUNDUP(((O33*1000*100)/(N33*P33)),0) -> #VALUE! | Y33: =IF(X33 <5, 5, X33) -> 5
A34: =1+A33 -> 31 | B34: SEE Civil Pad, Tailings Dam, Cadia | C34: Komatsu | D34: 155 / D155AX-6 | F34: Dozer | H34: 24 | I34: =IF(H34=24,(16+(16*0.03))," ") -> 16.48 | J34: 12v x2, 1050CCA, 160AH | K34: =160*3600/5 -> 115200 | L34: No Fuse instlled | M34: 70-7506 | N34: =IF(I34=16.48,16," ") -> 16 | O34: 11 | P34: 56.25 | Q34: =ROUNDUP(((O34*1000*100)/(N34*P34)),0) -> 1223 | R34: 680 | T34: 400 | U34: 1 | W34: 20 | X34: 4 | Y34: =IF(X34 <5, 5, X34) -> 5 | Z34: 35 | AB34: 1 | AD34: weldflex | AE34: 95 | AF34: 60 | AG34: 375 | AI34: 5
A35: =1+A34 -> 32 | B35: SEE Civil Pad, Tailings Dam, Cadia | C35: Komatsu | D35: 375/ D375-5E0 | F35: Dozer | H35: 24 | I35: =IF(H35=24,(16+(16*0.03))," ") -> 16.48 | J35: 12v x2, 1200CCA, 185AH | K35: =185*3600/5 -> 133200 | L35: 1000 | M35: NXS9724 | N35: =IF(I35=16.48,16," ") -> 16 | O35: 7.5 | P35: 56.25 | Q35: =ROUNDUP(((O35*1000*100)/(N35*P35)),0) -> 834 | R35: 960 | T35: 750 | U35: 1 | W35: 17 | X35: 4 | Y35: =IF(X35 <5, 5, X35) -> 5 | Z35: 60 | AB35: 1 | AD35: Weldflex | AE35: 95 | AF35: 60 | AG35: 375 | AH35: 750 | AI35: 4
A36: =1+A35 -> 33 | B36: SEE Civil Pad, Tailings Dam, Cadia | C36: Komatsu | D36: 120T/ PC1250-11 | F36: Excavator | H36: 24 | I36: =IF(H36=24,(16+(16*0.03))," ") -> 16.48 | M36: 70-7500G | N36: =IF(I36=16.48,16," ") -> 16 | O36: 11 | P36: 56.25 | Q36: =ROUNDUP(((O36*1000*100)/(N36*P36)),0) -> 1223 | Y36: =IF(X36 <5, 5, X36) -> 5
A37: =1+A36 -> 34 | B37: SEE Civil Pad, Tailings Dam, Cadia | C37: Komatsu | D37: D475 | F37: Dozer | I37: =IF(H37=24,(16+(16*0.03))," ") | M37: AESSTR117B | N37: =IF(I37=16.48,16," ") | O37: 7.5 | P37: 56.25 | Q37: =ROUNDUP(((O37*1000*100)/(N37*P37)),0) -> #VALUE! | Y37: =IF(X37 <5, 5, X37) -> 5 | Z37: 140
A38: =1+A37 -> 35 | B38: SEE Civil Pad, Tailings Dam, Cadia | C38: Komatsu | D38: HD465 | F38: Service_Truck | I38: =IF(H38=24,(16+(16*0.03))," ") | M38: Nikko | N38: =IF(I38=16.48,16," ") | O38: 7.5 | P38: 56.25 | Q38: =ROUNDUP(((O38*1000*100)/(N38*P38)),0) -> #VALUE! | Y38: =IF(X38 <5, 5, X38) -> 5 | Z38: 50
A39: =1+A38 -> 36 | B39: SEE Civil Pad, Tailings Dam, Cadia | C39: Komatsu | D39: WA1200 | F39: Loader | I39: =IF(H39=24,(16+(16*0.03))," ") | M39: Komatsu | N39: =IF(I39=16.48,16," ") | O39: 9 | P39: 56.25 | Q39: =ROUNDUP(((O39*1000*100)/(N39*P39)),0) -> #VALUE! | Y39: =IF(X39 <5, 5, X39) -> 5
D40: MD6250
...

Sheet StarterMotors Library
M1: Starter Motor | N1: Application | Q1: Manufacturer | R1: Model | S1: Link | T1: Manufacturer model | U1: Link | W1: Mech Power (kW) | X1: Motor Eff (%) | Y1: Elec power (kW) | Z1: Input V | AA1: Cranking Current (A)
A2: 50MT starter 24V | M2: 150MT,24V | N2: Catapillar C12,C13,C15 Detroit, Mack E7 | Q2: Caterpillar | R2: 293-4853: Motor Gp-Ele | S2: https://parts.cat.com/en/catcorp/293-4853 | W2: 4500 | X2: =0.5625 -> 0.5625 | Y2: =W2/X2 -> 8000 | Z2: 15 | AA2: =Y2/Z2 -> 533.33333
M3: 39MT,24V | N3: Caetrpillar C12,C13,C15 Detroit, Mack E7 | Q3: Caterpillar | R3: 542-5972: Air Starting Motor | S3: https://parts.cat.com/en/catcorp/542-5972 | W3: 7300 | X3: =0.5625 -> 0.5625 | Y3: =W3/X3 -> 12977.778 | Z3: 16 | AA3: =Y3/Z3 -> 811.11111
M4: 50MT,24V | N4: Cummins,Detroit,Caterpillar | Q4: Caterpillar | R4: 348-7651: Starting Motor Gp-Electric | S4: https://parts.cat.com/en/catcorp/348-7651 | W4: 7500 | X4: =0.5625 -> 0.5625 | Y4: =W4/X4 -> 13333.333 | Z4: 16 | AA4: =Y4/Z4 -> 833.33333
Q5: Caterpillar | R5: 349-9075: Motor Gp-Ele | S5: https://parts.cat.com/en/catcorp/349-9075 | W5: 7800 | X5: =0.5625 -> 0.5625 | Y5: =W5/X5 -> 13866.667 | Z5: 16 | AA5: =Y5/Z5 -> 866.66667
Q6: Caterpillar | R6: 357-7354: Motor Gp-Ele | S6: https://parts.cat.com/en/catcorp/357-7354 | T6: 24V, 9kW | W6: 9000 | X6: =0.5625 -> 0.5625 | Y6: =W6/X6 -> 16000 | Z6: 16 | AA6: =Y6/Z6 -> 1000
Q7: Caterpillar | R7: 488-2807 | S7: https://parts.cat.com/en/catcorp/488-2807 | T7: 24V, 7.8kW | W7: 11000 | X7: =0.5625 -> 0.5625 | Y7: =W7/X7 -> 19555.556 | Z7: 16 | AA7: =Y7/Z7 -> 1222.2222
Q8: Caterpillar | R8: 10R-0399 | S8: https://parts.cat.com/en/catcorp/10R-0399
Q9: Caterpillar | R9: 10R-0400 | S9: https://parts.cat.com/en/catcorp/10R-0400 | T9: 7.3kW, 24V, 42MT?
Q10: Caterpillar | R10: 594-8720 | S10: https://parts.cat.com/en/catcorp/594-8720 | T10: 24V, 11kW
Q11: Caterpillar | R11: 10R-9816 | S11: https://parts.cat.com/en/catcorp/10R-9816 | T11: 50 MT, 24V, 9kW | U11: https://www.delcoremy.com/starters/find-by-model-family/50mt
Q12: Caterpillar | R12: 6V-0885 | S12: https://parts.cat.com/en/catcorp/6V-0885 | T12: 9kW, 24V
Q13: Komatsu, Jaylec | R13: 70-7506 | S13: https://automotivesuperstore.com.au/jaylec-70-7506?srsltid=AfmBOoodEubfWCPZoTYth6mQP407kDmt-UF7AvhdG12mjfX67xAjjnD5 | T13: 24V, 11kW
Q14: Komatsu, Nikko | R14: NXS9724 | S14: https://www.zivorauto.com.au/nxs9724-nikko-starter-motor-24v-11th-cw-for-komats~5481250 | T14: 24V, 7.5 | U14: https://www.autoelectricalsuperstore.com.au/starter-motors-24-volt/7284-127423-starter-motor-nikko-24-volt-11th-cw.html#/751-make-komatsu/962-model-d375a_5_232l_sa6d170e_ohv_24v_turbo_diesel_direct_inj_6cyl_dozer/19023-year_to-0/19259-year_from-0
Q15: Caterpillar | R15: 20R-1312 | S15: https://parts.cat.com/en/catcorp/20R-1312 | T15: 24V, 9kW, 39MT | U15: https://www.vicautoparts.com.au/product/starter-motor-delco-39mt-9-0kw-24v-11t-56mm-cw-suits-caterpillar-c12-c13-c15-detroit-s60-mack-e7-cummins-isx-2/
Q16: Caterpillar | R16: 590-4756 | S16: https://parts.cat.com/en/catcorp/590-4756 | T16: 24V, 4.5kW
Q17: Caterpillar | R17: 357-5205 | S17: https://parts.cat.com/en/catcorp/357-5205 | T17: 24V, 4kW
Q18: Caterpillar | R18: 0R-4316 | S18: https://parts.cat.com/en/catcorp/0R-4316 | T18: 2.7kW, 12V
T19: 24V, 9kW | U19: https://www.rareelectrical.com/i-26899026-new-24v-12t-starter-motor-compatible-with-caterpillar-scraper-621-623-627b-637d-1109998-1990228.html
T20: 24V, 7.5kW | U20: https://www.amazon.com/Rareelectrical-37566-20500-0-23000-7740-0-23000-7741-0-23000-7742/dp/B0094BNL5W
T21: 24V, 8.5kW | U21: https://www.ebay.com.au/itm/305475666734?srsltid=AfmBOooxHZa8bVL_DoY72c6frGGfsL5moMMJ72kPMivkaqXIAdedOJBk
Q22: Isuzu | R22: S06-058G | S22: https://www.isuzu.com.au/Media/Isuzu_Files/Spec_Sheets/Current_spec_sheets/FYH_FYJ%20300-350%208x4_ARK1412_v04.pdf | T22: 24V, 5kW | U22: https://auto8.com.au/part/c/10002-electrics/b/auto-8/brand-new-starter-motor-fits-isuzu-npr200-npr250-npr300-npr400-nkr150-nkr200-nps300-elf-4-3l-diesel-engines/S06-058G.html
T23: 24V, 11kW | U23: https://www.rolan.com.au/nikko-starter-24v-11th-11kw-komatsu-pc1250-7-pc1250-8-wa600-3-wa600-6-nik-70-7500g.html?srsltid=AfmBOoq-DNsjZDp6sHNZYKOUM48stVa3WRve2HlgZa7FJ-xLpLyvpJWj
T24: 24V, 7.5kW | U24: https://www.rolan.com.au/nikko-starter-24v-11th-11kw-komatsu-pc1250-7-pc1250-8-wa600-3-wa600-6-nik-70-7500g.html?srsltid=AfmBOoq-DNsjZDp6sHNZYKOUM48stVa3WRve2HlgZa7FJ-xLpLyvpJWj
T25: 24V, 7.5kW | U25: https://www.rareelectrical.com/i-26880200-new-starter-motor-compatible-with-komatsu-dump-truck-hd465-5-600-813-7113-6008137113-0-23000-7770.html
Q26: Komatsu | S26: https://www.komatsu.jp/en/worldwide/PDF/WA1200-6_CEN00419-01.pdf | T26: 24, 9kW
A28: 37 MT 12V
A53: 42MT 24V
A85: 39 MT 12V

Sheet Fuse_Library
A1: GB PART # Fuse holder | B1: Manufacturer | C1: Description | D1: Manu Part # | E1: Current rating (A) | F1: I2t (A2s) | G1: Breaking current (A) | H1: Time to withstand current current (s) based on I2t | I1: Time to withstand current (s) based on graph | J1: Interrupting Rating | K1: Temperature range (DegC) | L1: Link | M1: Fuse rating (A) Options
A2: GB161280 | B2: Little Fuse | C2: MEGA 32V | D2: 298500.ZXH | E2: 500 | F2: 2050000 | G2: 1000 | H2: =F2/(G2*G2) -> 2.05 | I2: =IFERROR(INDEX(MEGA32V!$B$3:$F$10, MATCH(Fuse_Library!G2, MEGA32V!A$3:A$10, 0), MATCH(Fuse_Library!E2, MEGA32V!B$2:F$2, 0)), "NO MATCH") -> 10 | J2: 2000 A @ 32 V DC | K2: -40 to 125 | L2: https://www.littelfuse.com/products/fuses/automotive-passenger-car/high-current-fuses/298.aspx | M2: 125
A3: GB161280 | B3: Little Fuse | C3: MEGA 32V | D3: 298500.ZXH | E3: 500 | F3: 2050000 | G3: 1200 | H3: =ROUND((F3/(G3*G3)),2) -> 1.42 | I3: =IFERROR(INDEX(MEGA32V!$B$3:$F$10, MATCH(Fuse_Library!G3, MEGA32V!A$3:A$10, 0), MATCH(Fuse_Library!E3, MEGA32V!B$2:F$2, 0)), "NO MATCH") -> 5 | J3: 2000A @ 32V VDC | K3: -40 to 125 | L3: https://www.littelfuse.com/products/fuses/automotive-passenger-car/high-current-fuses/298.aspx | M3: =M2+25 -> 150
A4: GB161280 | B4: Little Fuse | C4: MEGA 32V | D4: 298450.ZXH | E4: 450 | F4: 1050000 | G4: 1000 | H4: =ROUND((F4/(G4*G4)),2) -> 1.05 | I4: =IFERROR(INDEX(MEGA32V!$B$3:$F$10, MATCH(Fuse_Library!G4, MEGA32V!A$3:A$10, 0), MATCH(Fuse_Library!E4, MEGA32V!B$2:F$2, 0)), "NO MATCH") -> 4 | J4: 2000A @ 32V VDC | K4: -40 to 126 | L4: https://www.littelfuse.com/products/fuses/automotive-passenger-car/high-current-fuses/298.aspx | M4: =M3+25 -> 175
A5: GB161280 | B5: Little Fuse | C5: MEGA 32V | D5: 298400.ZXH | E5: 400 | F5: 610000 | G5: 1000 | H5: =ROUND((F5/(G5*G5)),2) -> 0.61 | I5: =IFERROR(INDEX(MEGA32V!$B$3:$F$10, MATCH(Fuse_Library!G5, MEGA32V!A$3:A$10, 0), MATCH(Fuse_Library!E5, MEGA32V!B$2:F$2, 0)), "NO MATCH") -> 2 | J5: 2000A @ 32V VDC | K5: -40 to 127 | L5: https://www.littelfuse.com/products/fuses/automotive-passenger-car/high-current-fuses/298.aspx | M5: =M4+25 -> 200
A6: GB161280 | B6: Little Fuse | C6: MEGA 32V | D6: 298350.ZXH | E6: 350 | F6: 500000 | G6: 1000 | H6: =ROUND((F6/(G6*G6)),2) -> 0.5 | I6: =IFERROR(INDEX(MEGA32V!$B$3:$F$10, MATCH(Fuse_Library!G6, MEGA32V!A$3:A$10, 0), MATCH(Fuse_Library!E6, MEGA32V!B$2:F$2, 0)), "NO MATCH") -> 1.7 | J6: 2000A @ 32V VDC | K6: -40 to 128 | L6: https://www.littelfuse.com/products/fuses/automotive-passenger-car/high-current-fuses/298.aspx | M6: =M5+25 -> 225
A7: GB161280 | B7: Little Fuse | C7: MEGA 32V | D7: 298300.ZXH | E7: 300 | F7: 315000 | G7: 1000 | H7: =ROUND((F7/(G7*G7)),2) -> 0.32 | I7: =IFERROR(INDEX(MEGA32V!$B$3:$F$10, MATCH(Fuse_Library!G7, MEGA32V!A$3:A$10, 0), MATCH(Fuse_Library!E7, MEGA32V!B$2:F$2, 0)), "NO MATCH") -> 0.75 | J7: 2000A @ 32V VDC | K7: -40 to 129 | L7: https://www.littelfuse.com/products/fuses/automotive-passenger-car/high-current-fuses/298.aspx | M7: =M6+25 -> 250
A8: GB161280 | B8: Little Fuse | C8: MEGA 32V | D8: 298300.ZXH | E8: 300 | F8: 315000 | G8: 500 | H8: =ROUND((F8/(G8*G8)),2) -> 1.26 | I8: =IFERROR(INDEX(MEGA32V!$B$3:$F$10, MATCH(Fuse_Library!G8, MEGA32V!A$3:A$10, 0), MATCH(Fuse_Library!E8, MEGA32V!B$2:F$2, 0)), "NO MATCH") -> 10 | J8: 2000A @ 32V VDC | K8: -40 to 130 | L8: https://www.littelfuse.com/products/fuses/automotive-passenger-car/high-current-fuses/298.aspx | M8: =M7+25 -> 275
M9: =M8+25 -> 300
M10: =M9+25 -> 325
M11: =M10+25 -> 350
M12: =M11+25 -> 375
M13: =M12+25 -> 400
M14: =M13+100 -> 500
M15: =M14+25 -> 525
M16: =M15+25 -> 550
M17: =M16+25 -> 575
M18: =M17+25 -> 600
M19: =M18+25 -> 625
M20: =M19+25 -> 650
M21: =M20+25 -> 675
M22: =M21+25 -> 700
M23: =M22+25 -> 725
M24: =M23+25 -> 750
M25: =M24+25 -> 775
M26: =M25+25 -> 800
M27: =M26+25 -> 825
B41: rated current | D41: De rating factor | F41: Zcase | M41: Mega
B42: 500 | C42: 250 | D42: 200 | E42: 238 | F42: 199 | H42: 172 | J42: 375 | K42: 359 | L42: 338 | M42: 285 | N42: 258 | O42: 218 | P42: 190
C43: =($B$42-C42)/$B$42 -> 0.5 | D43: =($B$42-D42)/$B$42 -> 0.6 | E43: =($B$42-E42)/$B$42 -> 0.524 | F43: =($B$42-F42)/$B$42 -> 0.602 | H43: =($B$42-H42)/$B$42 -> 0.656 | J43: =($B$42-J42)/$B$42 -> 0.25 | K43: =($B$42-K42)/$B$42 -> 0.282 | L43: =($B$42-L42)/$B$42 -> 0.324 | M43: =($B$42-M42)/$B$42 -> 0.43 | N43: =($B$42-N42)/$B$42 -> 0.484 | O43: =($B$42-O42)/$B$42 -> 0.564 | P43: =($B$42-P42)/$B$42 -> 0.62

Sheet MEGA32V
A2: Crank Current (A)\Time (s) for each rated fuse | B2: 300 | C2: 350 | D2: 400 | E2: 450 | F2: 500
A3: 500 | B3: 10 | C3: 70 | D3: 100 | E3: 1300 | F3: inf
A4: =100+A3 -> 600 | B4: 5 | C4: 20 | D4: 25 | E4: 180 | F4: 1200
A5: 650 | B5: 3.5
A6: =100+A4 -> 700 | B6: 2.9 | C6: 7 | D6: 9 | E6: 40 | F6: 300
A7: =100+A6 -> 800 | B7: 1.8 | C7: 4 | D7: 5 | E7: 17 | F7: 100
A8: =100+A7 -> 900 | B8: 1.2 | C8: 2.4 | D8: 3 | E8: 7 | F8: 30
A9: =100+A8 -> 1000 | B9: 0.75 | C9: 1.7 | D9: 2 | E9: 4 | F9: 10
A10: 1200 | B10: 0.6 | C10: 0.8 | D10: 1.2 | E10: 2.2 | F10: 5

Sheet Cable_Capacity
A1: Cable Type | B1: Insulation Type | C1: K factor | D1: Installation method | E1: Maximum Conductor Temperature DegC | F1: Size (mm2) | G1: Current carrying Capacity (A) | H1: Resistance (ohm/km) | I1: 3 percent voltage drop distance (m) | K1: Cable Type | L1: Insulation Type | M1: K factor | N1: Installation method | O1: Maximum Conductor Temperature DegC | P1: Size (mm2) | Q1: Current carrying Capacity (A) | R1: Resistance (ohm/km) | S1: 3 percent voltage drop distance (m)
A2: Two Single Core | B2: X-90 , XLPE | C2: 143 | D2: Spaced from the surface, touching another cable, flexible & unenclosed | E2: 90 | F2: 120 | G2: 389 | H2: 0.188 | I2: 3.5 | K2: Two Single Core | L2: X-90 , XLPE | M2: 143 | N2: Enclosed | O2: 90 | P2: 120 | Q2: 286 | R2: 0.188 | S2: 4.7
A3: Two Single Core | B3: X-90 , XLPE | C3: 143 | D3: Spaced from the surface, touching another cable, flexible & unenclosed | E3: 90 | F3: 95 | G3: 328 | H3: 0.236 | I3: 3.3 | K3: Two Single Core | L3: X-90 , XLPE | M3: 143 | N3: Enclosed | O3: 90 | P3: 95 | Q3: 248 | R3: 0.236 | S3: 4.3
A4: Two Single Core | B4: X-90 , XLPE | C4: 143 | D4: Spaced from the surface, touching another cable, flexible & unenclosed | E4: 90 | F4: 70 | G4: 274 | H4: 0.327 | I4: 2.8 | K4: Two Single Core | L4: X-90 , XLPE | M4: 143 | N4: Enclosed | O4: 90 | P4: 70 | Q4: 204 | R4: 0.327 | S4: 3.8
A5: Two Single Core | B5: X-90 , XLPE | C5: 143 | D5: Spaced from the surface, touching another cable, flexible & unenclosed | E5: 90 | F5: 50 | G5: 218 | H5: 0.471 | I5: 2.5 | K5: Two Single Core | L5: X-90 , XLPE | M5: 143 | N5: Enclosed | O5: 90 | P5: 50 | Q5: 167 | R5: 0.471 | S5: 3.2
A7: Two Single Core | B7: X-110 , XLPE | C7: 150 | D7: Spaced from the surface, touching another cable, flexible & unenclosed | E7: 110 | F7: 120 | G7: 466 | H7: 0.188 | I7: 2.9 | K7: Two Single Core | L7: X-110 , XLPE | M7: 150 | N7: Enclosed | O7: 110 | P7: 120 | Q7: 364 | R7: 0.188 | S7: 3.7
A8: Two Single Core | B8: X-110 , XLPE | C8: 150 | D8: Spaced from the surface, touching another cable, flexible & unenclosed | E8: 110 | F8: 95 | G8: 395 | H8: 0.236 | I8: 2.7 | K8: Two Single Core | L8: X-110 , XLPE | M8: 150 | N8: Enclosed | O8: 110 | P8: 95 | Q8: 312 | R8: 0.236 | S8: 3.4
A9: Two Single Core | B9: X-110 , XLPE | C9: 150 | D9: Spaced from the surface, touching another cable, flexible & unenclosed | E9: 110 | F9: 70 | G9: 329 | H9: 0.327 | I9: 2.3 | K9: Two Single Core | L9: X-110 , XLPE | M9: 150 | N9: Enclosed | O9: 110 | P9: 70 | Q9: 263 | R9: 0.327 | S9: 2.9
A10: Two Single Core | B10: X-110 , XLPE | C10: 150 | D10: Spaced from the surface, touching another cable, flexible & unenclosed | E10: 110 | F10: 50 | G10: 263 | H10: 0.471 | I10: 2 | K10: Two Single Core | L10: X-110 , XLPE | M10: 150 | N10: Enclosed | O10: 110 | P10: 50 | Q10: 207 | R10: 0.471 | S10: 2.6
C15: Links
C16: https://www.jcalc.net/cable-sizing-calculator-as3008
C17: https://www.jcalc.net/cable-sizing-calculator-as3009
C18: https://www.jcalc.net/cable-sizing-calculator-as3010
C20: https://www.iqytechnicalcollege.com/AS3008.pdf
C22: The current ratings are selected from Tables 4 to 21 in AS/NZS 3008-2017. It is based on cable type, insulation type and the cable installation method.
C23: for 17 DC

Sheet WeldingCable
A1: Duty Cycle (%) | B1: Duration (s) | C1: Current Rating (A)
A2: 1 | B2: 15 | C2: 455 A
A3: 0.6 | B3: 9 | C3: 600-650 A (est.)
A4: 0.3 | B4: 4.5 | C4: 800-850 A (est.)
A5: 0.25 | B5: 3.75 | C5: 900 A (est.)
R6: chrome-extension://efaidnbmnnnibpcajpcglclefindmkaj/https://et.jenuincable.com/uploads/file/asnzs1995-2003-r2017-welding-cable.pdf

Sheet Popular_Cable_sizes
A1: Size (mm2) | B1: AWG | C1: Current (A) | D1: Insulation Type | E1: Temp (°C) | F1: Length (mm) | G1: Manufacturer | H1: Compatible category | I1: Compatible machine | J1: Link
A2: 120 | B2: 0000 | G2: Catepillar | H2: GENERATOR | I2: SR5 | J2: https://parts.cat.com/en/catcorp/130-0026
I3: SR4B
H4: GEN SET ENGINE | I4: DE1100 POWER SYS
H5: GENERATOR SET | I5: C32
I6: D1000
I7: DE1250
I8: C27
I9: C32
I10: GENSET
I11: D800
I12: DE1000S
H13: PETROLEUM PRODUCTS | I13: C27
I14: C32
H15: ENGINE - INDUSTRIAL | I15: C32 GENSET
H16: ENGINE - GENERATOR SET | I16: C32
I17: C27
H18: PETROLEUM GEN SET | I18: C32
A19: 70 | B19: 00 | F19: 190 | G19: Catepillar | H19: OFF-HIGHWAY TRUCK | I19: 777 | J19: https://parts.cat.com/en/westrac/110-5991
I20: 777C
I21: 776C
I22: 777D
I23: 777B
I24: 776D
I25: 785C
H26: WHEEL-TYPE LOADER | I26: 994
I27: 994D
I28: 992G
H29: TRUCK | I29: 777D
H30: EXCAVATOR | I30: 5230
I31: 5130
I32: 5230B
I33: 5130B
H34: WHEEL DOZER | I34: 854G
H35: WHEEL LOADER | I35: 992G
A36: 55 | B36: 0 | F36: 777 | G36: Catepillar | H36: OFF-HIGHWAY TRUCK | I36: 793F AC | J36: https://parts.cat.com/en/westrac/457-5212
H37: TRUCK | I37: 797F
I38: 797
I39: 793F
I40: 795F AC
...

Sheet Copper_K_Factor
B1: Value of k Conductor Material | F1: Temperature
A2: Cable Type | B2: Copper | C2: Copper high Temp | D2: Aluminium | E2: Steel | F2: Initial DegC | G2: Final DegC
A3: Thermoplastic 70°C (PVC) | B3: 115 | C3: 103 | D3: 76/78 | E3: 42/37 | F3: 70 | G3: 160/140
A4: Thermoplastic 90°C (PVC) | B4: 100 | C4: 86 | D4: 66/57 | E4: 36/31 | F4: 90 | G4: 160/140
A5: Thermosetting 90°C XLPE EDR | B5: 143 | D5: 94 | E5: 52 | F5: 90 | G5: 250
A6: Thermosetting 60°C rubber | B6: 141 | D6: 93 | E6: 51 | F6: 60 | G6: 200
A7: Thermosetting 85°C rubber | B7: 134 | D7: 89 | E7: 48 | F7: 85 | G7: 220
A8: Thermosetting 185°C silicone rubber | B8: 132 | D8: 87 | E8: 47 | F8: 180 | G8: 350
A9: Thermosetting 110°C XLPE | B9: 150 | H9: Need to verify
A10: OEM Wiring | B10: 143
A11: Weldflex | B11: 150 | H11: XLPE 110°C XLPE
A12: Weldflex PVC | B12: 115
A13: Narva | B13: 150
A25: These values are suitable for fault durations up to 5 seconds:
A26: Copper (because it’s the rockstar of conductors):
A27: Thermoplastic (70°C PVC): (k = 143)
A28: Thermosetting (90°C XLPE or EPR): (k = 143)
A29: Thermosetting (60°C rubber): (k = 141)
A30: Thermosetting (85°C rubber): (k = 134)
A31: Thermosetting (185°C silicone rubber): (k = 132)
A32: Aluminium (also cool, but not as rockstar as copper):
A33: Thermoplastic (70°C PVC): (k = 103)
A34: Thermosetting (90°C XLPE or EPR): (k = 94)
A35: Thermosetting (60°C rubber): (k = 93)
A36: Thermosetting (85°C rubber): (k = 89)
... A43: Thermosetting (185°C silicone rubber): (k = 47)

Sheet Alternators24V Library
A1: Manufacturer | B1: Name | C1: O/p current (A) | D1: Application
A2: Delco | B2: 55SI brusless alternator | C2: 250&275 | D2: utility & work trucks, fire trucks, and long haul trucks, wheel loaders, graders and mining equipment
B3: 36SI brushless alternator | C3: 105 | D3: N/A
B4: 34SI brushless alternator | C4: 75&100 | D4: medium and heavy duty applications
B5: 33SI brushless alternator | C5: 75&100 | D5: large electrical load requirements.
B6: 28SI brushless alternator | C6: 110 | D6: higher electrical output, but also want lower weigh
A7: Denso | B7: Denso Alternator 24V 95A | C7: 95 | D7: N/A
B8: Alternator 100-50244 | C8: 150 | D8: Caterpillar
B9: Alternator 24V 150A | C9: 150 | D9: Sandvik LH517 & LH621
A10: CAT | B10: Alternator 24V 95A | C10: 95 | D10: CAT R3000
A11: Unknown | B11: Alternator 24V 140A | C11: 140 | D11: MT6020

Sheet CableInquiry
A1: Email Sent to the Company about cables | B1: Cable Size Available | C1: Datasheet
A2: AlanMance
A3: Australian Power equipment
A4: Autocables
A5: Automegastore
A6: Automotive Supoerstore
A7: Baxters
A8: Blue Bar Industries
A9: CableCraft
A10: CableCraft
A11: Caterpillar
A12: Chain System Australia
A13: CMI Electrical
... A55: ZeroGrid

Sheet StandardComplaince
A1: Standard Compliance - Design Guidelines: AS/NZS 5000.1 - Conductor: As/NZS 1125 - Insulation and Sheath: AS/NZS 3808 - Current Carrying Capacity: AS/NZS 3008.1.1:2009 (Table 9, Touching) - Flame Retardant: IEC 60332-1-2 - Low Smoke: IEC61034-2 - Halogen Free: IEC 60754-2

Sheet MD6250 Project
A1: GIVEN/ASSUMPTION | L1: EQUATIONS
A2: Components | B2: Parameter | C2: Unit | D2: Value
A3: Starter Motor (50MT, unless stated otherwise) | B3: System voltage | C3: V | D3: 24
B4: Voltage at peak power/lowest operating voltage (Graph) | C4: V | D4: 16
B5: Output Power | C5: kW | D5: 9
B6: # of motors | C6: N/A | D6: 2
B7: Efficiency of the starter motor at ambient temperature (Assumption) | C7: % | D7: 70
B8: Efficiency at cold temperature (worse case) (Assumption) | C8: % | D8: 50
B9: Typical cranking Speed (Assumption) | C9: RPM | D9: 180
B10: 150MT Starting torque gear ratio | C10: N/A | D10: 4.3
B11: 150MT Gearing efficiency in cold climate (Assumption) | C11: % | D11: 70
B12: Motor Constant (Assumption) | C12: NM/A | D12: 0.1
A13: Drill Engine | B13: Type | C13: N/A | D13: C27
B14: Engine Displacement | C14: L | D14: 27.03
B15: Engine Efficiency | C15: % | D15: 60
B16: Compression Ratio | C16: N/A | D16: 16.5
B17: Starter motor configuration | C17: N/A | D17: Parallel
A18: Load | B18: Percentage of Starter Torque (Assumption) | C18: % | D18: 80
A19: Fuse | B19: Fuse rating gain (Assumption) | C19: % | D19: 125
A20: Battery | B20: Type | C20: N/A | D20: n200
B21: Voltage | C21: V | D21: 12
B22: # Series | C22: N/A | D22: 2
B23: Total voltage | C23: V | D23: =D22*D21 -> 24
B24: Cranking Amps | C24: A | D24: 1200
A25: Cabling | B25: Size | C25: mm2 | D25: 107 | L25: Load Current = Load torque /(Motor constant * Motor voltage)
B26: Guage | C26: ga | D26: 4/0 or 0000
A29: CALCULATION | D29: 16 volt
A30: Components | B30: Parameter | C30: Unit | D30: 1X50MT | E30: 2x50MT
A31: Starter motor | B31: Mechanical Power at peak torque | C31: kW | D31: =ROUND((D9*D32/9548),0) -> 4 | E31: =D31*2 -> 8
B32: Total output torque available | C32: Nm | D32: 200 | E32: =D32*2 -> 400
B33: Total Electrical Power required at ambient temp | C33: kW | D33: =ROUND((D31*(D7/100)),0) -> 3 | E33: =ROUND((E31/(D7/100)),0) -> 11
B34: Total Electrical Power due to cold temperature | C34: kW | D34: =D31/(D8/100) -> 8 | E34: =E31/(D8/100) -> 16
B35: Cranking amps at ambient temperature (Graph) | C35: A | D35: 1000 | E35: =2*D35 -> 2000
B36: Cranking amps at cold temperature | C36: A | D36: =D35*1.5 -> 1500 | E36: =2*D36 -> 3000
A37: Fuse | B37: 125% of the peak current during ambient temp | C37: A | D37: =ROUND((($D$19/100)*D35),0) -> 1250 | E37: =2*D37 -> 2500 | F37: This needs to change to the safety margin and needs to 125% of the load current demand and not peak. We need it to break the circuit before or close 80% of the peak value
B38: 125% of the peak current during cold temp | C38: A | D38: =ROUND((($D$19/100)*D36),0) -> 1875 | E38: =2*D38 -> 3750
B42: 50-MT starting motor performance graph
B68: Source:
A69: https://www.google.com/url?sa=i&url=https%3A%2F%2Fwww.deer-online.com%2Fstarter-remy-10478888-art-en_10478888_dre&psig=AOvVaw25ErWACyqzg7kcuguJX9pA&ust=1715735593188000&source=images&cd=vfe&opi=89978449&ved=0CBIQjRxqFwoTCMiS4rD7i4YDFQAAAAAdAAAAABAE

Sheet R&D
A1: Load current
A2: Derating Factor
A3: Fuse Current | B3: Load current/Derating Factor
E30: Motors should be fused with a time-delay fuse rated 175% of the motor's full load operating amperage, 250% of the full load operating amperage if a circuit breaker is used. The wire to a motor must be rated to carry 25% more amperage than the motor draws when operating at full load.
E31: https://groverelectric.com/assets/downloads/howto/20_How%20to%20Calculate%20Wire%20&%20Fuse%20Sizes%20for%20Electric%20Motors.pdf

Sheet list values
A1: Cranking current options (A) | B1: Continous current option (A) | C1: Cranking Amps (A)
A2: 0 | B2: 80 | C2: 200
A3: =200+A2 -> 200 | B3: =1+B2 -> 81 | C3: =C2+1 -> 201
A4: =200+A3 -> 400 | B4: =1+B3 -> 82 | C4: =C3+1 -> 202
A5: =200+A4 -> 600 | B5: =1+B4 -> 83 | C5: =C4+1 -> 203
A6: =200+A5 -> 800 | B6: =1+B5 -> 84 | C6: =C5+1 -> 204
A7: =200+A6 -> 1000 | B7: =1+B6 -> 85 | C7: =C6+1 -> 205
A8: =200+A7 -> 1200 | B8: =1+B7 -> 86 | C8: =C7+1 -> 206
A9: =200+A8 -> 1400 | B9: =1+B8 -> 87 | C9: =C8+1 -> 207
A10: =200+A9 -> 1600 | B10: =1+B9 -> 88 | C10: =C9+1 -> 208
A11: =200+A10 -> 1800 | B11: =1+B10 -> 89 | C11: =C10+1 -> 209
A12: =200+A11 -> 2000 | B12: =1+B11 -> 90 | C12: =C11+1 -> 210
A13: =200+A12 -> 2200 | B13: =1+B12 -> 91 | C13: =C12+1 -> 211
A14: =200+A13 -> 2400 | B14: =1+B13 -> 92 | C14: =C13+1 -> 212
... A47: =200+A46 -> 9000 | B47: =1+B46 -> 125 | C47: =C46+1 -> 245
B48: =1+B47 -> 126 | C48: =C47+1 -> 246
B49: =1+B48 -> 127 | C49: =C48+1 -> 247
B50: =1+B49 -> 128 | C50: =C49+1 -> 248
B51: =1+B50 -> 129 | C51: =C50+1 -> 249
B52: =1+B51 -> 130 | C52: =C51+1 -> 250
B53: =1+B52 -> 131 | C53: =C52+1 -> 251
B54: =1+B53 -> 132 | C54: =C53+1 -> 252
B55: =1+B54 -> 133 | C55: =C54+1 -> 253
B56: =1+B55 -> 134 | C56: =C55+1 -> 254
B57: =1+B56 -> 135 | C57: =C56+1 -> 255
B58: =1+B57 -> 136 | C58: =C57+1 -> 256
B59: =1+B58 -> 137 | C59: =C58+1 -> 257
... B422: =1+B421 -> 500 | C422: =C421+1 -> 620
C423: =C422+1 -> 621
C424: =C423+1 -> 622
C425: =C424+1 -> 623
C426: =C425+1 -> 624
C427: =C426+1 -> 625
C428: =C427+1 -> 626
C429: =C428+1 -> 627
C430: =C429+1 -> 628
C431: =C430+1 -> 629
C432: =C431+1 -> 630
C433: =C432+1 -> 631
C434: =C433+1 -> 632
...
